<?xml version="1.0" encoding="UTF-8"?>
<testng-results skipped="0" failed="9" total="13" passed="4">
  <reporter-output>
  </reporter-output>
  <suite name="Suite" duration-ms="2130" started-at="2017-09-14T05:37:02Z" finished-at="2017-09-14T05:37:04Z">
    <groups>
    </groups>
    <test name="Test" duration-ms="2130" started-at="2017-09-14T05:37:02Z" finished-at="2017-09-14T05:37:04Z">
      <class name="exe.Arthadb_Automation">
        <test-method status="FAIL" signature="ArthaDB_ProdCodes_Check_TC001()[pri:0, instance:exe.Arthadb_Automation@5700d6b1]" name="ArthaDB_ProdCodes_Check_TC001" duration-ms="750" started-at="2017-09-14T11:07:02Z" finished-at="2017-09-14T11:07:03Z">
          <exception class="junit.framework.AssertionFailedError">
            <message>
              <![CDATA[AUDIT-Product Codes check is Failed at UniqueID=J901891D18902,J911620FS4904, expected:<0> but was:<2>]]>
            </message>
            <full-stacktrace>
              <![CDATA[junit.framework.AssertionFailedError: AUDIT-Product Codes check is Failed at UniqueID=J901891D18902,J911620FS4904, expected:<0> but was:<2>
	at junit.framework.Assert.fail(Assert.java:57)
	at junit.framework.Assert.failNotEquals(Assert.java:329)
	at junit.framework.Assert.assertEquals(Assert.java:78)
	at junit.framework.Assert.assertEquals(Assert.java:234)
	at exe.Arthadb_Automation.ArthaDB_ProdCodes_Check_TC001(Arthadb_Automation.java:65)
	at sun.reflect.NativeMethodAccessorImpl.invoke0(Native Method)
	at sun.reflect.NativeMethodAccessorImpl.invoke(Unknown Source)
	at sun.reflect.DelegatingMethodAccessorImpl.invoke(Unknown Source)
	at java.lang.reflect.Method.invoke(Unknown Source)
	at org.testng.internal.MethodInvocationHelper.invokeMethod(MethodInvocationHelper.java:80)
	at org.testng.internal.Invoker.invokeMethod(Invoker.java:714)
	at org.testng.internal.Invoker.invokeTestMethod(Invoker.java:901)
	at org.testng.internal.Invoker.invokeTestMethods(Invoker.java:1231)
	at org.testng.internal.TestMethodWorker.invokeTestMethods(TestMethodWorker.java:127)
	at org.testng.internal.TestMethodWorker.run(TestMethodWorker.java:111)
	at org.testng.TestRunner.privateRun(TestRunner.java:767)
	at org.testng.TestRunner.run(TestRunner.java:617)
	at org.testng.SuiteRunner.runTest(SuiteRunner.java:334)
	at org.testng.SuiteRunner.runSequentially(SuiteRunner.java:329)
	at org.testng.SuiteRunner.privateRun(SuiteRunner.java:291)
	at org.testng.SuiteRunner.run(SuiteRunner.java:240)
	at org.testng.SuiteRunnerWorker.runSuite(SuiteRunnerWorker.java:52)
	at org.testng.SuiteRunnerWorker.run(SuiteRunnerWorker.java:86)
	at org.testng.TestNG.runSuitesSequentially(TestNG.java:1198)
	at org.testng.TestNG.runSuitesLocally(TestNG.java:1123)
	at org.testng.TestNG.run(TestNG.java:1031)
	at org.testng.remote.AbstractRemoteTestNG.run(AbstractRemoteTestNG.java:132)
	at org.testng.remote.RemoteTestNG.initAndRun(RemoteTestNG.java:230)
	at org.testng.remote.RemoteTestNG.main(RemoteTestNG.java:76)
]]>
            </full-stacktrace>
          </exception> <!-- junit.framework.AssertionFailedError -->
          <reporter-output>
          </reporter-output>
        </test-method> <!-- ArthaDB_ProdCodes_Check_TC001 -->
        <test-method status="FAIL" signature="ArthaDB_AuditDates_Check_TC002()[pri:0, instance:exe.Arthadb_Automation@5700d6b1]" name="ArthaDB_AuditDates_Check_TC002" duration-ms="128" started-at="2017-09-14T11:07:03Z" finished-at="2017-09-14T11:07:03Z">
          <exception class="junit.framework.AssertionFailedError">
            <message>
              <![CDATA[AUDIT-Exp and Eff Date check is Failed at UniqueID=D3527056787843525678, expected:<0> but was:<1>]]>
            </message>
            <full-stacktrace>
              <![CDATA[junit.framework.AssertionFailedError: AUDIT-Exp and Eff Date check is Failed at UniqueID=D3527056787843525678, expected:<0> but was:<1>
	at junit.framework.Assert.fail(Assert.java:57)
	at junit.framework.Assert.failNotEquals(Assert.java:329)
	at junit.framework.Assert.assertEquals(Assert.java:78)
	at junit.framework.Assert.assertEquals(Assert.java:234)
	at exe.Arthadb_Automation.ArthaDB_AuditDates_Check_TC002(Arthadb_Automation.java:109)
	at sun.reflect.NativeMethodAccessorImpl.invoke0(Native Method)
	at sun.reflect.NativeMethodAccessorImpl.invoke(Unknown Source)
	at sun.reflect.DelegatingMethodAccessorImpl.invoke(Unknown Source)
	at java.lang.reflect.Method.invoke(Unknown Source)
	at org.testng.internal.MethodInvocationHelper.invokeMethod(MethodInvocationHelper.java:80)
	at org.testng.internal.Invoker.invokeMethod(Invoker.java:714)
	at org.testng.internal.Invoker.invokeTestMethod(Invoker.java:901)
	at org.testng.internal.Invoker.invokeTestMethods(Invoker.java:1231)
	at org.testng.internal.TestMethodWorker.invokeTestMethods(TestMethodWorker.java:127)
	at org.testng.internal.TestMethodWorker.run(TestMethodWorker.java:111)
	at org.testng.TestRunner.privateRun(TestRunner.java:767)
	at org.testng.TestRunner.run(TestRunner.java:617)
	at org.testng.SuiteRunner.runTest(SuiteRunner.java:334)
	at org.testng.SuiteRunner.runSequentially(SuiteRunner.java:329)
	at org.testng.SuiteRunner.privateRun(SuiteRunner.java:291)
	at org.testng.SuiteRunner.run(SuiteRunner.java:240)
	at org.testng.SuiteRunnerWorker.runSuite(SuiteRunnerWorker.java:52)
	at org.testng.SuiteRunnerWorker.run(SuiteRunnerWorker.java:86)
	at org.testng.TestNG.runSuitesSequentially(TestNG.java:1198)
	at org.testng.TestNG.runSuitesLocally(TestNG.java:1123)
	at org.testng.TestNG.run(TestNG.java:1031)
	at org.testng.remote.AbstractRemoteTestNG.run(AbstractRemoteTestNG.java:132)
	at org.testng.remote.RemoteTestNG.initAndRun(RemoteTestNG.java:230)
	at org.testng.remote.RemoteTestNG.main(RemoteTestNG.java:76)
]]>
            </full-stacktrace>
          </exception> <!-- junit.framework.AssertionFailedError -->
          <reporter-output>
          </reporter-output>
        </test-method> <!-- ArthaDB_AuditDates_Check_TC002 -->
        <test-method status="FAIL" signature="ArthaDB_Account_Number_Check_TC003()[pri:0, instance:exe.Arthadb_Automation@5700d6b1]" name="ArthaDB_Account_Number_Check_TC003" duration-ms="108" started-at="2017-09-14T11:07:03Z" finished-at="2017-09-14T11:07:03Z">
          <exception class="junit.framework.AssertionFailedError">
            <message>
              <![CDATA[PAYMENTS-Account Number check is Failed at Invoice_Number=J91606706e6C122, expected:<0> but was:<1>]]>
            </message>
            <full-stacktrace>
              <![CDATA[junit.framework.AssertionFailedError: PAYMENTS-Account Number check is Failed at Invoice_Number=J91606706e6C122, expected:<0> but was:<1>
	at junit.framework.Assert.fail(Assert.java:57)
	at junit.framework.Assert.failNotEquals(Assert.java:329)
	at junit.framework.Assert.assertEquals(Assert.java:78)
	at junit.framework.Assert.assertEquals(Assert.java:234)
	at exe.Arthadb_Automation.ArthaDB_Account_Number_Check_TC003(Arthadb_Automation.java:153)
	at sun.reflect.NativeMethodAccessorImpl.invoke0(Native Method)
	at sun.reflect.NativeMethodAccessorImpl.invoke(Unknown Source)
	at sun.reflect.DelegatingMethodAccessorImpl.invoke(Unknown Source)
	at java.lang.reflect.Method.invoke(Unknown Source)
	at org.testng.internal.MethodInvocationHelper.invokeMethod(MethodInvocationHelper.java:80)
	at org.testng.internal.Invoker.invokeMethod(Invoker.java:714)
	at org.testng.internal.Invoker.invokeTestMethod(Invoker.java:901)
	at org.testng.internal.Invoker.invokeTestMethods(Invoker.java:1231)
	at org.testng.internal.TestMethodWorker.invokeTestMethods(TestMethodWorker.java:127)
	at org.testng.internal.TestMethodWorker.run(TestMethodWorker.java:111)
	at org.testng.TestRunner.privateRun(TestRunner.java:767)
	at org.testng.TestRunner.run(TestRunner.java:617)
	at org.testng.SuiteRunner.runTest(SuiteRunner.java:334)
	at org.testng.SuiteRunner.runSequentially(SuiteRunner.java:329)
	at org.testng.SuiteRunner.privateRun(SuiteRunner.java:291)
	at org.testng.SuiteRunner.run(SuiteRunner.java:240)
	at org.testng.SuiteRunnerWorker.runSuite(SuiteRunnerWorker.java:52)
	at org.testng.SuiteRunnerWorker.run(SuiteRunnerWorker.java:86)
	at org.testng.TestNG.runSuitesSequentially(TestNG.java:1198)
	at org.testng.TestNG.runSuitesLocally(TestNG.java:1123)
	at org.testng.TestNG.run(TestNG.java:1031)
	at org.testng.remote.AbstractRemoteTestNG.run(AbstractRemoteTestNG.java:132)
	at org.testng.remote.RemoteTestNG.initAndRun(RemoteTestNG.java:230)
	at org.testng.remote.RemoteTestNG.main(RemoteTestNG.java:76)
]]>
            </full-stacktrace>
          </exception> <!-- junit.framework.AssertionFailedError -->
          <reporter-output>
          </reporter-output>
        </test-method> <!-- ArthaDB_Account_Number_Check_TC003 -->
        <test-method status="FAIL" signature="ArthaDB_ChargeType_Check_TC004()[pri:0, instance:exe.Arthadb_Automation@5700d6b1]" name="ArthaDB_ChargeType_Check_TC004" duration-ms="75" started-at="2017-09-14T11:07:03Z" finished-at="2017-09-14T11:07:03Z">
          <exception class="junit.framework.AssertionFailedError">
            <message>
              <![CDATA[PAYMENTS-Charge Type check is Failed at Account_Number(s)=ACCD101N8776123, expected:<0> but was:<1>]]>
            </message>
            <full-stacktrace>
              <![CDATA[junit.framework.AssertionFailedError: PAYMENTS-Charge Type check is Failed at Account_Number(s)=ACCD101N8776123, expected:<0> but was:<1>
	at junit.framework.Assert.fail(Assert.java:57)
	at junit.framework.Assert.failNotEquals(Assert.java:329)
	at junit.framework.Assert.assertEquals(Assert.java:78)
	at junit.framework.Assert.assertEquals(Assert.java:234)
	at exe.Arthadb_Automation.ArthaDB_ChargeType_Check_TC004(Arthadb_Automation.java:197)
	at sun.reflect.NativeMethodAccessorImpl.invoke0(Native Method)
	at sun.reflect.NativeMethodAccessorImpl.invoke(Unknown Source)
	at sun.reflect.DelegatingMethodAccessorImpl.invoke(Unknown Source)
	at java.lang.reflect.Method.invoke(Unknown Source)
	at org.testng.internal.MethodInvocationHelper.invokeMethod(MethodInvocationHelper.java:80)
	at org.testng.internal.Invoker.invokeMethod(Invoker.java:714)
	at org.testng.internal.Invoker.invokeTestMethod(Invoker.java:901)
	at org.testng.internal.Invoker.invokeTestMethods(Invoker.java:1231)
	at org.testng.internal.TestMethodWorker.invokeTestMethods(TestMethodWorker.java:127)
	at org.testng.internal.TestMethodWorker.run(TestMethodWorker.java:111)
	at org.testng.TestRunner.privateRun(TestRunner.java:767)
	at org.testng.TestRunner.run(TestRunner.java:617)
	at org.testng.SuiteRunner.runTest(SuiteRunner.java:334)
	at org.testng.SuiteRunner.runSequentially(SuiteRunner.java:329)
	at org.testng.SuiteRunner.privateRun(SuiteRunner.java:291)
	at org.testng.SuiteRunner.run(SuiteRunner.java:240)
	at org.testng.SuiteRunnerWorker.runSuite(SuiteRunnerWorker.java:52)
	at org.testng.SuiteRunnerWorker.run(SuiteRunnerWorker.java:86)
	at org.testng.TestNG.runSuitesSequentially(TestNG.java:1198)
	at org.testng.TestNG.runSuitesLocally(TestNG.java:1123)
	at org.testng.TestNG.run(TestNG.java:1031)
	at org.testng.remote.AbstractRemoteTestNG.run(AbstractRemoteTestNG.java:132)
	at org.testng.remote.RemoteTestNG.initAndRun(RemoteTestNG.java:230)
	at org.testng.remote.RemoteTestNG.main(RemoteTestNG.java:76)
]]>
            </full-stacktrace>
          </exception> <!-- junit.framework.AssertionFailedError -->
          <reporter-output>
          </reporter-output>
        </test-method> <!-- ArthaDB_ChargeType_Check_TC004 -->
        <test-method status="FAIL" signature="ArthaDB_Invoice_Number_Check_TC005()[pri:0, instance:exe.Arthadb_Automation@5700d6b1]" name="ArthaDB_Invoice_Number_Check_TC005" duration-ms="35" started-at="2017-09-14T11:07:03Z" finished-at="2017-09-14T11:07:03Z">
          <exception class="junit.framework.AssertionFailedError">
            <message>
              <![CDATA[PAYMENTS-Invoice Number check is Failed at Account_Number(s)=ACCD101N9990884, expected:<0> but was:<1>]]>
            </message>
            <full-stacktrace>
              <![CDATA[junit.framework.AssertionFailedError: PAYMENTS-Invoice Number check is Failed at Account_Number(s)=ACCD101N9990884, expected:<0> but was:<1>
	at junit.framework.Assert.fail(Assert.java:57)
	at junit.framework.Assert.failNotEquals(Assert.java:329)
	at junit.framework.Assert.assertEquals(Assert.java:78)
	at junit.framework.Assert.assertEquals(Assert.java:234)
	at exe.Arthadb_Automation.ArthaDB_Invoice_Number_Check_TC005(Arthadb_Automation.java:241)
	at sun.reflect.NativeMethodAccessorImpl.invoke0(Native Method)
	at sun.reflect.NativeMethodAccessorImpl.invoke(Unknown Source)
	at sun.reflect.DelegatingMethodAccessorImpl.invoke(Unknown Source)
	at java.lang.reflect.Method.invoke(Unknown Source)
	at org.testng.internal.MethodInvocationHelper.invokeMethod(MethodInvocationHelper.java:80)
	at org.testng.internal.Invoker.invokeMethod(Invoker.java:714)
	at org.testng.internal.Invoker.invokeTestMethod(Invoker.java:901)
	at org.testng.internal.Invoker.invokeTestMethods(Invoker.java:1231)
	at org.testng.internal.TestMethodWorker.invokeTestMethods(TestMethodWorker.java:127)
	at org.testng.internal.TestMethodWorker.run(TestMethodWorker.java:111)
	at org.testng.TestRunner.privateRun(TestRunner.java:767)
	at org.testng.TestRunner.run(TestRunner.java:617)
	at org.testng.SuiteRunner.runTest(SuiteRunner.java:334)
	at org.testng.SuiteRunner.runSequentially(SuiteRunner.java:329)
	at org.testng.SuiteRunner.privateRun(SuiteRunner.java:291)
	at org.testng.SuiteRunner.run(SuiteRunner.java:240)
	at org.testng.SuiteRunnerWorker.runSuite(SuiteRunnerWorker.java:52)
	at org.testng.SuiteRunnerWorker.run(SuiteRunnerWorker.java:86)
	at org.testng.TestNG.runSuitesSequentially(TestNG.java:1198)
	at org.testng.TestNG.runSuitesLocally(TestNG.java:1123)
	at org.testng.TestNG.run(TestNG.java:1031)
	at org.testng.remote.AbstractRemoteTestNG.run(AbstractRemoteTestNG.java:132)
	at org.testng.remote.RemoteTestNG.initAndRun(RemoteTestNG.java:230)
	at org.testng.remote.RemoteTestNG.main(RemoteTestNG.java:76)
]]>
            </full-stacktrace>
          </exception> <!-- junit.framework.AssertionFailedError -->
          <reporter-output>
          </reporter-output>
        </test-method> <!-- ArthaDB_Invoice_Number_Check_TC005 -->
        <test-method status="PASS" signature="ArthaDB_Transaction_Amount_Check_TC006()[pri:0, instance:exe.Arthadb_Automation@5700d6b1]" name="ArthaDB_Transaction_Amount_Check_TC006" duration-ms="66" started-at="2017-09-14T11:07:03Z" finished-at="2017-09-14T11:07:03Z">
          <reporter-output>
          </reporter-output>
        </test-method> <!-- ArthaDB_Transaction_Amount_Check_TC006 -->
        <test-method status="FAIL" signature="ArthaDB_ChargeSign_Check_TC007()[pri:0, instance:exe.Arthadb_Automation@5700d6b1]" name="ArthaDB_ChargeSign_Check_TC007" duration-ms="48" started-at="2017-09-14T11:07:03Z" finished-at="2017-09-14T11:07:03Z">
          <exception class="junit.framework.AssertionFailedError">
            <message>
              <![CDATA[PAYMENTS-Charge Sign Codes check is Failed at Account_Number=ACCD101N8776123, expected:<0> but was:<1>]]>
            </message>
            <full-stacktrace>
              <![CDATA[junit.framework.AssertionFailedError: PAYMENTS-Charge Sign Codes check is Failed at Account_Number=ACCD101N8776123, expected:<0> but was:<1>
	at junit.framework.Assert.fail(Assert.java:57)
	at junit.framework.Assert.failNotEquals(Assert.java:329)
	at junit.framework.Assert.assertEquals(Assert.java:78)
	at junit.framework.Assert.assertEquals(Assert.java:234)
	at exe.Arthadb_Automation.ArthaDB_ChargeSign_Check_TC007(Arthadb_Automation.java:329)
	at sun.reflect.NativeMethodAccessorImpl.invoke0(Native Method)
	at sun.reflect.NativeMethodAccessorImpl.invoke(Unknown Source)
	at sun.reflect.DelegatingMethodAccessorImpl.invoke(Unknown Source)
	at java.lang.reflect.Method.invoke(Unknown Source)
	at org.testng.internal.MethodInvocationHelper.invokeMethod(MethodInvocationHelper.java:80)
	at org.testng.internal.Invoker.invokeMethod(Invoker.java:714)
	at org.testng.internal.Invoker.invokeTestMethod(Invoker.java:901)
	at org.testng.internal.Invoker.invokeTestMethods(Invoker.java:1231)
	at org.testng.internal.TestMethodWorker.invokeTestMethods(TestMethodWorker.java:127)
	at org.testng.internal.TestMethodWorker.run(TestMethodWorker.java:111)
	at org.testng.TestRunner.privateRun(TestRunner.java:767)
	at org.testng.TestRunner.run(TestRunner.java:617)
	at org.testng.SuiteRunner.runTest(SuiteRunner.java:334)
	at org.testng.SuiteRunner.runSequentially(SuiteRunner.java:329)
	at org.testng.SuiteRunner.privateRun(SuiteRunner.java:291)
	at org.testng.SuiteRunner.run(SuiteRunner.java:240)
	at org.testng.SuiteRunnerWorker.runSuite(SuiteRunnerWorker.java:52)
	at org.testng.SuiteRunnerWorker.run(SuiteRunnerWorker.java:86)
	at org.testng.TestNG.runSuitesSequentially(TestNG.java:1198)
	at org.testng.TestNG.runSuitesLocally(TestNG.java:1123)
	at org.testng.TestNG.run(TestNG.java:1031)
	at org.testng.remote.AbstractRemoteTestNG.run(AbstractRemoteTestNG.java:132)
	at org.testng.remote.RemoteTestNG.initAndRun(RemoteTestNG.java:230)
	at org.testng.remote.RemoteTestNG.main(RemoteTestNG.java:76)
]]>
            </full-stacktrace>
          </exception> <!-- junit.framework.AssertionFailedError -->
          <reporter-output>
          </reporter-output>
        </test-method> <!-- ArthaDB_ChargeSign_Check_TC007 -->
        <test-method status="FAIL" signature="ArthaDB_Record_Type_Check_TC008()[pri:0, instance:exe.Arthadb_Automation@5700d6b1]" name="ArthaDB_Record_Type_Check_TC008" duration-ms="89" started-at="2017-09-14T11:07:03Z" finished-at="2017-09-14T11:07:03Z">
          <exception class="junit.framework.AssertionFailedError">
            <message>
              <![CDATA[PAYMENTS-Record Type check is Failed at Invoice_Number=J9908844423C102,J91606706e6C122, expected:<0> but was:<2>]]>
            </message>
            <full-stacktrace>
              <![CDATA[junit.framework.AssertionFailedError: PAYMENTS-Record Type check is Failed at Invoice_Number=J9908844423C102,J91606706e6C122, expected:<0> but was:<2>
	at junit.framework.Assert.fail(Assert.java:57)
	at junit.framework.Assert.failNotEquals(Assert.java:329)
	at junit.framework.Assert.assertEquals(Assert.java:78)
	at junit.framework.Assert.assertEquals(Assert.java:234)
	at exe.Arthadb_Automation.ArthaDB_Record_Type_Check_TC008(Arthadb_Automation.java:373)
	at sun.reflect.NativeMethodAccessorImpl.invoke0(Native Method)
	at sun.reflect.NativeMethodAccessorImpl.invoke(Unknown Source)
	at sun.reflect.DelegatingMethodAccessorImpl.invoke(Unknown Source)
	at java.lang.reflect.Method.invoke(Unknown Source)
	at org.testng.internal.MethodInvocationHelper.invokeMethod(MethodInvocationHelper.java:80)
	at org.testng.internal.Invoker.invokeMethod(Invoker.java:714)
	at org.testng.internal.Invoker.invokeTestMethod(Invoker.java:901)
	at org.testng.internal.Invoker.invokeTestMethods(Invoker.java:1231)
	at org.testng.internal.TestMethodWorker.invokeTestMethods(TestMethodWorker.java:127)
	at org.testng.internal.TestMethodWorker.run(TestMethodWorker.java:111)
	at org.testng.TestRunner.privateRun(TestRunner.java:767)
	at org.testng.TestRunner.run(TestRunner.java:617)
	at org.testng.SuiteRunner.runTest(SuiteRunner.java:334)
	at org.testng.SuiteRunner.runSequentially(SuiteRunner.java:329)
	at org.testng.SuiteRunner.privateRun(SuiteRunner.java:291)
	at org.testng.SuiteRunner.run(SuiteRunner.java:240)
	at org.testng.SuiteRunnerWorker.runSuite(SuiteRunnerWorker.java:52)
	at org.testng.SuiteRunnerWorker.run(SuiteRunnerWorker.java:86)
	at org.testng.TestNG.runSuitesSequentially(TestNG.java:1198)
	at org.testng.TestNG.runSuitesLocally(TestNG.java:1123)
	at org.testng.TestNG.run(TestNG.java:1031)
	at org.testng.remote.AbstractRemoteTestNG.run(AbstractRemoteTestNG.java:132)
	at org.testng.remote.RemoteTestNG.initAndRun(RemoteTestNG.java:230)
	at org.testng.remote.RemoteTestNG.main(RemoteTestNG.java:76)
]]>
            </full-stacktrace>
          </exception> <!-- junit.framework.AssertionFailedError -->
          <reporter-output>
          </reporter-output>
        </test-method> <!-- ArthaDB_Record_Type_Check_TC008 -->
        <test-method status="FAIL" signature="ArthaDB_Customer_FirstName_Check_TC009()[pri:0, instance:exe.Arthadb_Automation@5700d6b1]" name="ArthaDB_Customer_FirstName_Check_TC009" duration-ms="93" started-at="2017-09-14T11:07:03Z" finished-at="2017-09-14T11:07:03Z">
          <exception class="junit.framework.AssertionFailedError">
            <message>
              <![CDATA[CUSTOMERS-First Name check is Failed at SSN=824-553-4629, expected:<0> but was:<1>]]>
            </message>
            <full-stacktrace>
              <![CDATA[junit.framework.AssertionFailedError: CUSTOMERS-First Name check is Failed at SSN=824-553-4629, expected:<0> but was:<1>
	at junit.framework.Assert.fail(Assert.java:57)
	at junit.framework.Assert.failNotEquals(Assert.java:329)
	at junit.framework.Assert.assertEquals(Assert.java:78)
	at junit.framework.Assert.assertEquals(Assert.java:234)
	at exe.Arthadb_Automation.ArthaDB_Customer_FirstName_Check_TC009(Arthadb_Automation.java:417)
	at sun.reflect.NativeMethodAccessorImpl.invoke0(Native Method)
	at sun.reflect.NativeMethodAccessorImpl.invoke(Unknown Source)
	at sun.reflect.DelegatingMethodAccessorImpl.invoke(Unknown Source)
	at java.lang.reflect.Method.invoke(Unknown Source)
	at org.testng.internal.MethodInvocationHelper.invokeMethod(MethodInvocationHelper.java:80)
	at org.testng.internal.Invoker.invokeMethod(Invoker.java:714)
	at org.testng.internal.Invoker.invokeTestMethod(Invoker.java:901)
	at org.testng.internal.Invoker.invokeTestMethods(Invoker.java:1231)
	at org.testng.internal.TestMethodWorker.invokeTestMethods(TestMethodWorker.java:127)
	at org.testng.internal.TestMethodWorker.run(TestMethodWorker.java:111)
	at org.testng.TestRunner.privateRun(TestRunner.java:767)
	at org.testng.TestRunner.run(TestRunner.java:617)
	at org.testng.SuiteRunner.runTest(SuiteRunner.java:334)
	at org.testng.SuiteRunner.runSequentially(SuiteRunner.java:329)
	at org.testng.SuiteRunner.privateRun(SuiteRunner.java:291)
	at org.testng.SuiteRunner.run(SuiteRunner.java:240)
	at org.testng.SuiteRunnerWorker.runSuite(SuiteRunnerWorker.java:52)
	at org.testng.SuiteRunnerWorker.run(SuiteRunnerWorker.java:86)
	at org.testng.TestNG.runSuitesSequentially(TestNG.java:1198)
	at org.testng.TestNG.runSuitesLocally(TestNG.java:1123)
	at org.testng.TestNG.run(TestNG.java:1031)
	at org.testng.remote.AbstractRemoteTestNG.run(AbstractRemoteTestNG.java:132)
	at org.testng.remote.RemoteTestNG.initAndRun(RemoteTestNG.java:230)
	at org.testng.remote.RemoteTestNG.main(RemoteTestNG.java:76)
]]>
            </full-stacktrace>
          </exception> <!-- junit.framework.AssertionFailedError -->
          <reporter-output>
          </reporter-output>
        </test-method> <!-- ArthaDB_Customer_FirstName_Check_TC009 -->
        <test-method status="PASS" signature="ArthaDB_Record_Type_Check_TC010()[pri:0, instance:exe.Arthadb_Automation@5700d6b1]" name="ArthaDB_Record_Type_Check_TC010" duration-ms="47" started-at="2017-09-14T11:07:03Z" finished-at="2017-09-14T11:07:03Z">
          <reporter-output>
          </reporter-output>
        </test-method> <!-- ArthaDB_Record_Type_Check_TC010 -->
        <test-method status="FAIL" signature="ArthaDB_Record_Type_Check_TC011()[pri:0, instance:exe.Arthadb_Automation@5700d6b1]" name="ArthaDB_Record_Type_Check_TC011" duration-ms="70" started-at="2017-09-14T11:07:03Z" finished-at="2017-09-14T11:07:04Z">
          <exception class="junit.framework.AssertionFailedError">
            <message>
              <![CDATA[PARTNERS-Record Type check is Failed at Partner_Account_Number=15914697799,25710135206, expected:<0> but was:<2>]]>
            </message>
            <full-stacktrace>
              <![CDATA[junit.framework.AssertionFailedError: PARTNERS-Record Type check is Failed at Partner_Account_Number=15914697799,25710135206, expected:<0> but was:<2>
	at junit.framework.Assert.fail(Assert.java:57)
	at junit.framework.Assert.failNotEquals(Assert.java:329)
	at junit.framework.Assert.assertEquals(Assert.java:78)
	at junit.framework.Assert.assertEquals(Assert.java:234)
	at exe.Arthadb_Automation.ArthaDB_Record_Type_Check_TC011(Arthadb_Automation.java:508)
	at sun.reflect.NativeMethodAccessorImpl.invoke0(Native Method)
	at sun.reflect.NativeMethodAccessorImpl.invoke(Unknown Source)
	at sun.reflect.DelegatingMethodAccessorImpl.invoke(Unknown Source)
	at java.lang.reflect.Method.invoke(Unknown Source)
	at org.testng.internal.MethodInvocationHelper.invokeMethod(MethodInvocationHelper.java:80)
	at org.testng.internal.Invoker.invokeMethod(Invoker.java:714)
	at org.testng.internal.Invoker.invokeTestMethod(Invoker.java:901)
	at org.testng.internal.Invoker.invokeTestMethods(Invoker.java:1231)
	at org.testng.internal.TestMethodWorker.invokeTestMethods(TestMethodWorker.java:127)
	at org.testng.internal.TestMethodWorker.run(TestMethodWorker.java:111)
	at org.testng.TestRunner.privateRun(TestRunner.java:767)
	at org.testng.TestRunner.run(TestRunner.java:617)
	at org.testng.SuiteRunner.runTest(SuiteRunner.java:334)
	at org.testng.SuiteRunner.runSequentially(SuiteRunner.java:329)
	at org.testng.SuiteRunner.privateRun(SuiteRunner.java:291)
	at org.testng.SuiteRunner.run(SuiteRunner.java:240)
	at org.testng.SuiteRunnerWorker.runSuite(SuiteRunnerWorker.java:52)
	at org.testng.SuiteRunnerWorker.run(SuiteRunnerWorker.java:86)
	at org.testng.TestNG.runSuitesSequentially(TestNG.java:1198)
	at org.testng.TestNG.runSuitesLocally(TestNG.java:1123)
	at org.testng.TestNG.run(TestNG.java:1031)
	at org.testng.remote.AbstractRemoteTestNG.run(AbstractRemoteTestNG.java:132)
	at org.testng.remote.RemoteTestNG.initAndRun(RemoteTestNG.java:230)
	at org.testng.remote.RemoteTestNG.main(RemoteTestNG.java:76)
]]>
            </full-stacktrace>
          </exception> <!-- junit.framework.AssertionFailedError -->
          <reporter-output>
          </reporter-output>
        </test-method> <!-- ArthaDB_Record_Type_Check_TC011 -->
        <test-method status="PASS" signature="ArthaDB_Premise_City_Check_TC012()[pri:0, instance:exe.Arthadb_Automation@5700d6b1]" name="ArthaDB_Premise_City_Check_TC012" duration-ms="28" started-at="2017-09-14T11:07:04Z" finished-at="2017-09-14T11:07:04Z">
          <reporter-output>
          </reporter-output>
        </test-method> <!-- ArthaDB_Premise_City_Check_TC012 -->
      </class> <!-- exe.Arthadb_Automation -->
      <class name="exe.ExcelRun">
        <test-method status="PASS" signature="f()[pri:0, instance:exe.ExcelRun@4566e5bd]" name="f" duration-ms="437" started-at="2017-09-14T11:07:04Z" finished-at="2017-09-14T11:07:04Z">
          <reporter-output>
          </reporter-output>
        </test-method> <!-- f -->
      </class> <!-- exe.ExcelRun -->
    </test> <!-- Test -->
  </suite> <!-- Suite -->
</testng-results>
